Workbook

Sheet Home
B2: Sold Direct
B3: Financial Model & Fundraising Materials
B5: MODEL INPUTS
B6: Assumptions | C6: Every input the model runs on — pricing, deal volumes, opex, tax & valuation multiple
B8: FINANCIALS
B9: P&L (Base) | C9: 5-year base-case income statement, EBITDA and after-tax cash proxy
B10: Scenarios | C10: Conservative / Base / Aggressive comparison and capital-need sizing
B12: MARKET
B13: Market Sizing | C13: TAM / SAM / SOM build and stress tests
B14: Competitive Landscape | C14: How Sold Direct compares to agencies, portals and bond originators
B15: Ancillary Revenue | C15: Optional ecosystem revenue streams (off by default in the P&L)
B17: FUNDRAISING
B18: Capital & Valuation | C18: Capital need by scenario, recommended raise, and valuation framing
B19: Use of Funds | C19: How the R5m raise is allocated
B20: Cap Table | C20: Ownership through Founding → Seed → Series A → Exit
B21: Funder Growth | C21: Return multiples by holder at Seed, Series A and Exit
B23: REFERENCE
B24: Notes & Sources | C24: Data sources, methodology notes and key watch-outs

Sheet Assumptions
B1: Sold Direct — Model Assumptions (Prime · 1% fee · technology-lean · bank sponsor)
B2: Amber = editable input. Grey = calculated. Every other tab links here.
B4: GLOBAL INPUTS
B5: Bond origination referral (% of bond, via BetterBond — Y1 only) | C5: 0.005
B6: Facilitation fee — non-partner deals (% of price) | C6: 0.01
B7: Gross margin | C7: 0.88
B8: ZAR per USD | C8: 18.5
B9: Valuation multiple — low (x revenue) | C9: 4
B10: Valuation multiple — high (x revenue) | C10: 6
B11: Working-capital / contingency buffer (R) | C11: 3000000
B13: PER-YEAR REVENUE DRIVERS (BASE)
C14: Y1 | D14: Y2 | E14: Y3 | F14: Y4 | G14: Y5
B15: Avg transacting price (R) | C15: 6500000 | D15: 5750000 | E15: 5000000 | F15: 4500000 | G15: 4000000
B16: Bonded share (qualifying >=80% bond, any bank) | C16: 0.4 | D16: 0.4 | E16: 0.4 | F16: 0.42 | G16: 0.42
B17: Bond size = 90% of price (R) | C17: =C15*0.9 | D17: =D15*0.9 | E17: =E15*0.9 | F17: =F15*0.9 | G17: =G15*0.9
B18: Origination income / qualifying deal (R) (Y1 ooba → Y2+ in-house) | C18: =C17*C67 | D18: =D17*D67 | E18: =E17*E67 | F18: =F17*F67 | G18: =G17*G67
B19: Facilitation fee / non-partner deal (R) | C19: =C15*$C$6 | D19: =D15*$C$6 | E19: =E15*$C$6 | F19: =F15*$C$6 | G19: =G15*$C$6
B20: Referral OR fee / deal, blended (R) | C20: =C16*C18+(1-C16)*C19 | D20: =D16*D18+(1-D16)*D19 | E20: =E16*E18+(1-E16)*E19 | F20: =F16*F18+(1-F16)*F19 | G20: =G16*G18+(1-G16)*G19
B21: Conveyancing referral / deal (R) — REMOVED: LPC prohibits attorney referral fees; panel discount (30–40%) now passes to the consumer | C21: 0 | D21: 0 | E21: 0 | F21: 0 | G21: 0
B22: Add-ons / deal (R) | C22: 5000 | D22: 5000 | E22: 5500 | F22: 6000 | G22: 6500
B23: Revenue per deal (R) | C23: =C20+C21+C22 | D23: =D20+D21+D22 | E23: =E20+E21+E22 | F23: =F20+F21+F22 | G23: =G20+G21+G22
B25: OTHER REVENUE
C26: Y1 | D26: Y2 | E26: Y3 | F26: Y4 | G26: Y5
B27: Bank headline sponsorship (R/yr) | C27: 3000000 | D27: 4000000 | E27: 5000000 | F27: 6500000 | G27: 8000000
B28: Conveyancer panel advertising (R/yr) — fixed subscriptions, volume-independent (LPC-compliant; benchmark vs portal ad rates) | C28: 360000 | D28: 720000 | E28: 1200000 | F28: 1800000 | G28: 2400000
B29: REGISTERED DEALS BY SCENARIO (reinvest-for-growth)
C30: Y1 | D30: Y2 | E30: Y3 | F30: Y4 | G30: Y5
B31: Conservative | C31: 30 | D31: 65 | E31: 200 | F31: 475 | G31: 950
B32: Base | C32: 50 | D32: 110 | E32: 325 | F32: 750 | G32: 1450
B33: Aggressive | C33: 80 | D33: 175 | E33: 500 | F33: 1200 | G33: 2400
B35: REVENUE/DEAL MULTIPLIER BY SCENARIO
B36: Conservative | C36: 0.92
B37: Base | C37: 1
B38: Aggressive | C38: 1.1
B40: OPERATING EXPENSE INPUTS (BASE) — Y1–Y2: four-person launch team, no office, Paysoft free-dev allocation
C41: Y1 | D41: Y2 | E41: Y3 | F41: Y4 | G41: Y5
B42: Total headcount (workers) | C42: 4 | D42: 6 | E42: 11 | F42: 25 | G42: 48
B43: Automated share of headcount | C43: 0 | D43: 0 | E43: 0.5 | F43: 0.5 | G43: 0.5
B44: Human FTEs | C44: =C42*(1-C43) | D44: =D42*(1-D43) | E44: =E42*(1-E43) | F44: =F42*(1-F43) | G44: =G42*(1-G43)
B45: automated roles | C45: =C42*C43 | D45: =D42*D43 | E45: =E42*E43 | F45: =F42*F43 | G45: =G42*G43
...

Sheet P&L (Base)
B1: Base Case P&L (R unless noted)
C3: Y1 | D3: Y2 | E3: Y3 | F3: Y4 | G3: Y5
B4: Registered deals | C4: =Assumptions!C32 | D4: =Assumptions!D32 | E4: =Assumptions!E32 | F4: =Assumptions!F32 | G4: =Assumptions!G32
B5: Revenue per deal (R, incl. ancillary if on) | C5: =Assumptions!C23*Assumptions!$C$37+Assumptions!$C$63 | D5: =Assumptions!D23*Assumptions!$C$37+Assumptions!$C$63 | E5: =Assumptions!E23*Assumptions!$C$37+Assumptions!$C$63 | F5: =Assumptions!F23*Assumptions!$C$37+Assumptions!$C$63 | G5: =Assumptions!G23*Assumptions!$C$37+Assumptions!$C$63
B6: Transactional revenue | C6: =C4*C5 | D6: =D4*D5 | E6: =E4*E5 | F6: =F4*F5 | G6: =G4*G5
B7: Bank sponsorship + conveyancer panel advertising | C7: =Assumptions!C27+Assumptions!C28 | D7: =Assumptions!D27+Assumptions!D28 | E7: =Assumptions!E27+Assumptions!E28 | F7: =Assumptions!F27+Assumptions!F28 | G7: =Assumptions!G27+Assumptions!G28
B8: Total revenue | C8: =C6+C7 | D8: =D6+D7 | E8: =E6+E7 | F8: =F6+F7 | G8: =G6+G7
B9: COGS | C9: =-C8*(1-Assumptions!$C$7) | D9: =-D8*(1-Assumptions!$C$7) | E9: =-E8*(1-Assumptions!$C$7) | F9: =-F8*(1-Assumptions!$C$7) | G9: =-G8*(1-Assumptions!$C$7)
B10: Gross profit | C10: =C8*Assumptions!$C$7 | D10: =D8*Assumptions!$C$7 | E10: =E8*Assumptions!$C$7 | F10: =F8*Assumptions!$C$7 | G10: =G8*Assumptions!$C$7
B11: Gross margin | C11: =IF(C8=0,"",C10/C8) | D11: =IF(D8=0,"",D10/D8) | E11: =IF(E8=0,"",E10/E8) | F11: =IF(F8=0,"",F10/F8) | G11: =IF(G8=0,"",G10/G8)
B12: Payroll + automated roles | C12: =Assumptions!C48 | D12: =Assumptions!D48 | E12: =Assumptions!E48 | F12: =Assumptions!F48 | G12: =Assumptions!G48
B13: Marketing | C13: =Assumptions!C49 | D13: =Assumptions!D49 | E13: =Assumptions!E49 | F13: =Assumptions!F49 | G13: =Assumptions!G49
B14: Tech & tools | C14: =Assumptions!C50 | D14: =Assumptions!D50 | E14: =Assumptions!E50 | F14: =Assumptions!F50 | G14: =Assumptions!G50
B15: Legal / compliance / insurance | C15: =Assumptions!C51 | D15: =Assumptions!D51 | E15: =Assumptions!E51 | F15: =Assumptions!F51 | G15: =Assumptions!G51
B16: G&A / office / other | C16: =Assumptions!C52 | D16: =Assumptions!D52 | E16: =Assumptions!E52 | F16: =Assumptions!F52 | G16: =Assumptions!G52
B17: Bond origination (in-house) | C17: =Assumptions!C72 | D17: =Assumptions!D72 | E17: =Assumptions!E72 | F17: =Assumptions!F72 | G17: =Assumptions!G72
B18: Total operating expenses | C18: =SUM(C12:C17) | D18: =SUM(D12:D17) | E18: =SUM(E12:E17) | F18: =SUM(F12:F17) | G18: =SUM(G12:G17)
B19: EBITDA | C19: =C10-C18 | D19: =D10-D18 | E19: =E10-E18 | F19: =F10-F18 | G19: =G10-G18
B20: EBITDA margin | C20: =IF(C8=0,"",C19/C8) | D20: =IF(D8=0,"",D19/D8) | E20: =IF(E8=0,"",E19/E8) | F20: =IF(F8=0,"",F19/F8) | G20: =IF(G8=0,"",G19/G8)
B21: Tax expense (SA corp rate, positive EBITDA only) | C21: =-MAX(0,C19)*Assumptions!$C$76 | D21: =-MAX(0,D19)*Assumptions!$C$76 | E21: =-MAX(0,E19)*Assumptions!$C$76 | F21: =-MAX(0,F19)*Assumptions!$C$76 | G21: =-MAX(0,G19)*Assumptions!$C$76
B22: EBITDA after tax | C22: =C19+C21 | D22: =D19+D21 | E22: =E19+E21 | F22: =F19+F21 | G22: =G19+G21
B23: Cumulative EBITDA after tax (cash proxy) | C23: =C22 | D23: =C23+D22 | E23: =D23+E22 | F23: =E23+F22 | G23: =F23+G22
B26: BUDGET SANITY CHECKS (growth vs. cost scaling)
B27: Total headcount (people + automated roles) | C27: =Assumptions!C42 | D27: =Assumptions!D42 | E27: =Assumptions!E42 | F27: =Assumptions!F42 | G27: =Assumptions!G42
B28: Human FTEs | C28: =Assumptions!C44 | D28: =Assumptions!D44 | E28: =Assumptions!E44 | F28: =Assumptions!F44 | G28: =Assumptions!G44
B29: Deals per headcount (productivity) | C29: =C4/C27 | D29: =D4/D27 | E29: =E4/E27 | F29: =F4/F27 | G29: =G4/G27
B30: Deals per human FTE | C30: =C4/C28 | D30: =D4/D28 | E30: =E4/E28 | F30: =F4/F28 | G30: =G4/G28
B31: Marketing spend / deal (R) | C31: =C13/C4 | D31: =D13/D4 | E31: =E13/E4 | F31: =F13/F4 | G31: =G13/G4
B32: Marketing % of revenue | C32: =C13/C8 | D32: =D13/D8 | E32: =E13/E8 | F32: =F13/F8 | G32: =G13/G8
B33: Payroll + automation % of revenue | C33: =C12/C8 | D33: =D12/D8 | E33: =E12/E8 | F33: =F12/F8 | G33: =G12/G8
B34: Total opex % of revenue | C34: =C18/C8 | D34: =D18/D8 | E34: =E18/E8 | F34: =F18/F8 | G34: =G18/G8
B35: YoY revenue growth % | D35: =D8/C8-1 | E35: =E8/D8-1 | F35: =F8/E8-1 | G35: =G8/F8-1
B36: YoY opex growth % | D36: =D18/C18-1 | E36: =E18/D18-1 | F36: =F18/E18-1 | G36: =G18/F18-1

Sheet COGS Build
B1: Bottom-Up COGS — Direct Cost per Registered Deal
B2: Itemised unit economics behind the P&L COGS line. Validates the 12% (88% gross margin) placeholder — see Annual Validation below.
B4: COGS COMPONENTS — PER DEAL (R)
B5: Line item | C5: Low (R/deal) | D5: High (R/deal) | E5: Blended (R/deal) | F5: What it is
B6: Platform & messaging (WhatsApp/BSP) | C6: 300 | D6: 400 | E6: =AVERAGE(C6:D6) | F6: Meta conversation fees + BSP markup across the enquiry funnel
B7: FICA / KYC / AML + affordability | C7: 220 | D7: 250 | E7: =AVERAGE(C7:D7) | F7: ID, bank & credit-bureau checks (multi-party)
B8: E-signature & digital docs | C8: 150 | D8: 180 | E8: =AVERAGE(C8:D8) | F8: Mandate, OTP, FICA, disclosures
B9: Property data / AVM / deeds / CMA | C9: 250 | D9: 300 | E9: =AVERAGE(C9:D9) | F9: Valuation & pricing data, deeds searches
B10: Listing media & portal syndication | C10: 1900 | D10: 3500 | E10: =AVERAGE(C10:D10) | F10: Photo/video/floorplan + Property24/PP fees, amortised incl. unsold listings
B11: Add-on / compliance-cert fulfilment | C11: 2900 | D11: 3800 | E11: =AVERAGE(C11:D11) | F11: Cost side of the CoC + photography add-ons we resell
B12: Other / contingency & per-deal SaaS | C12: 500 | D12: 600 | E12: =AVERAGE(C12:D12) | F12: Buffer + minor tooling
B13: Total COGS per deal (excl. payment processing) | E13: =SUM(E6:E12)
B14: Payment processing (% of collected revenue) | C14: 0.006
B16: Excludes (modelled elsewhere): bond-origination consultant cost (own P&L line from the Y2 change) and the concierge team (payroll/opex).
B18: ANNUAL VALIDATION vs. P&L (BASE)
C19: ='P&L (Base)'!C3 | D19: ='P&L (Base)'!D3 | E19: ='P&L (Base)'!E3 | F19: ='P&L (Base)'!F3 | G19: ='P&L (Base)'!G3
B20: Registered deals | C20: ='P&L (Base)'!C4 | D20: ='P&L (Base)'!D4 | E20: ='P&L (Base)'!E4 | F20: ='P&L (Base)'!F4 | G20: ='P&L (Base)'!G4
B21: Total revenue (R) | C21: ='P&L (Base)'!C8 | D21: ='P&L (Base)'!D8 | E21: ='P&L (Base)'!E8 | F21: ='P&L (Base)'!F8 | G21: ='P&L (Base)'!G8
B22: Bottom-up COGS — per-deal cost | C22: =C20*$E$13 | D22: =D20*$E$13 | E22: =E20*$E$13 | F22: =F20*$E$13 | G22: =G20*$E$13
B23: Bottom-up COGS — payment processing | C23: =C21*$C$14 | D23: =D21*$C$14 | E23: =E21*$C$14 | F23: =F21*$C$14 | G23: =G21*$C$14
B24: Total bottom-up COGS (R) | C24: =C22+C23 | D24: =D22+D23 | E24: =E22+E23 | F24: =F22+F23 | G24: =G22+G23
B25: Implied COGS % of revenue (bottom-up) | C25: =C24/C21 | D25: =D24/D21 | E25: =E24/E21 | F25: =F24/F21 | G25: =G24/G21
B26: P&L placeholder COGS % (=1-gross margin) | C26: =1-Assumptions!$C$7 | D26: =1-Assumptions!$C$7 | E26: =1-Assumptions!$C$7 | F26: =1-Assumptions!$C$7 | G26: =1-Assumptions!$C$7
B27: Variance (bottom-up vs. placeholder, pp) | C27: =C25-C26 | D27: =D25-D26 | E27: =E25-E26 | F27: =F25-F26 | G27: =G25-G26

Sheet Scenarios
B1: Scenario Comparison (R)
B3: CONSERVATIVE
C4: Y1 | D4: Y2 | E4: Y3 | F4: Y4 | G4: Y5
B5: Revenue | C5: =Assumptions!C31*(Assumptions!C23*Assumptions!$C$36+Assumptions!$C$63)+(Assumptions!C27+Assumptions!C28) | D5: =Assumptions!D31*(Assumptions!D23*Assumptions!$C$36+Assumptions!$C$63)+(Assumptions!D27+Assumptions!D28) | E5: =Assumptions!E31*(Assumptions!E23*Assumptions!$C$36+Assumptions!$C$63)+(Assumptions!E27+Assumptions!E28) | F5: =Assumptions!F31*(Assumptions!F23*Assumptions!$C$36+Assumptions!$C$63)+(Assumptions!F27+Assumptions!F28) | G5: =Assumptions!G31*(Assumptions!G23*Assumptions!$C$36+Assumptions!$C$63)+(Assumptions!G27+Assumptions!G28)
B6: Gross profit | C6: =C5*Assumptions!$C$7 | D6: =D5*Assumptions!$C$7 | E6: =E5*Assumptions!$C$7 | F6: =F5*Assumptions!$C$7 | G6: =G5*Assumptions!$C$7
B7: Operating expenses | C7: =Assumptions!C51+Assumptions!C52+(Assumptions!C48+Assumptions!C49+Assumptions!C50+Assumptions!C72)*Assumptions!$C$56 | D7: =Assumptions!D51+Assumptions!D52+(Assumptions!D48+Assumptions!D49+Assumptions!D50+Assumptions!D72)*Assumptions!$C$56 | E7: =Assumptions!E51+Assumptions!E52+(Assumptions!E48+Assumptions!E49+Assumptions!E50+Assumptions!E72)*Assumptions!$C$56 | F7: =Assumptions!F51+Assumptions!F52+(Assumptions!F48+Assumptions!F49+Assumptions!F50+Assumptions!F72)*Assumptions!$C$56 | G7: =Assumptions!G51+Assumptions!G52+(Assumptions!G48+Assumptions!G49+Assumptions!G50+Assumptions!G72)*Assumptions!$C$56
B8: EBITDA | C8: =C6-C7 | D8: =D6-D7 | E8: =E6-E7 | F8: =F6-F7 | G8: =G6-G7
B9: Cumulative EBITDA | C9: =C8 | D9: =C9+D8 | E9: =D9+E8 | F9: =E9+F8 | G9: =F9+G8
B10: profit-year helper | C10: =IF(C8>0,C$60,99) | D10: =IF(D8>0,D$60,99) | E10: =IF(E8>0,E$60,99) | F10: =IF(F8>0,F$60,99) | G10: =IF(G8>0,G$60,99)
B13: BASE
C14: Y1 | D14: Y2 | E14: Y3 | F14: Y4 | G14: Y5
B15: Revenue | C15: =Assumptions!C32*(Assumptions!C23*Assumptions!$C$37+Assumptions!$C$63)+(Assumptions!C27+Assumptions!C28) | D15: =Assumptions!D32*(Assumptions!D23*Assumptions!$C$37+Assumptions!$C$63)+(Assumptions!D27+Assumptions!D28) | E15: =Assumptions!E32*(Assumptions!E23*Assumptions!$C$37+Assumptions!$C$63)+(Assumptions!E27+Assumptions!E28) | F15: =Assumptions!F32*(Assumptions!F23*Assumptions!$C$37+Assumptions!$C$63)+(Assumptions!F27+Assumptions!F28) | G15: =Assumptions!G32*(Assumptions!G23*Assumptions!$C$37+Assumptions!$C$63)+(Assumptions!G27+Assumptions!G28)
B16: Gross profit | C16: =C15*Assumptions!$C$7 | D16: =D15*Assumptions!$C$7 | E16: =E15*Assumptions!$C$7 | F16: =F15*Assumptions!$C$7 | G16: =G15*Assumptions!$C$7
B17: Operating expenses | C17: =Assumptions!C53*Assumptions!$C$57 | D17: =Assumptions!D53*Assumptions!$C$57 | E17: =Assumptions!E53*Assumptions!$C$57 | F17: =Assumptions!F53*Assumptions!$C$57 | G17: =Assumptions!G53*Assumptions!$C$57
B18: EBITDA | C18: =C16-C17 | D18: =D16-D17 | E18: =E16-E17 | F18: =F16-F17 | G18: =G16-G17
B19: Cumulative EBITDA | C19: =C18 | D19: =C19+D18 | E19: =D19+E18 | F19: =E19+F18 | G19: =F19+G18
B20: profit-year helper | C20: =IF(C18>0,C$60,99) | D20: =IF(D18>0,D$60,99) | E20: =IF(E18>0,E$60,99) | F20: =IF(F18>0,F$60,99) | G20: =IF(G18>0,G$60,99)
B23: AGGRESSIVE
C24: Y1 | D24: Y2 | E24: Y3 | F24: Y4 | G24: Y5
B25: Revenue | C25: =Assumptions!C33*(Assumptions!C23*Assumptions!$C$38+Assumptions!$C$63)+(Assumptions!C27+Assumptions!C28) | D25: =Assumptions!D33*(Assumptions!D23*Assumptions!$C$38+Assumptions!$C$63)+(Assumptions!D27+Assumptions!D28) | E25: =Assumptions!E33*(Assumptions!E23*Assumptions!$C$38+Assumptions!$C$63)+(Assumptions!E27+Assumptions!E28) | F25: =Assumptions!F33*(Assumptions!F23*Assumptions!$C$38+Assumptions!$C$63)+(Assumptions!F27+Assumptions!F28) | G25: =Assumptions!G33*(Assumptions!G23*Assumptions!$C$38+Assumptions!$C$63)+(Assumptions!G27+Assumptions!G28)
B26: Gross profit | C26: =C25*Assumptions!$C$7 | D26: =D25*Assumptions!$C$7 | E26: =E25*Assumptions!$C$7 | F26: =F25*Assumptions!$C$7 | G26: =G25*Assumptions!$C$7
B27: Operating expenses | C27: =Assumptions!C51+Assumptions!C52+(Assumptions!C48+Assumptions!C49+Assumptions!C50+Assumptions!C72)*Assumptions!$C$58 | D27: =Assumptions!D51+Assumptions!D52+(Assumptions!D48+Assumptions!D49+Assumptions!D50+Assumptions!D72)*Assumptions!$C$58 | E27: =Assumptions!E51+Assumptions!E52+(Assumptions!E48+Assumptions!E49+Assumptions!E50+Assumptions!E72)*Assumptions!$C$58 | F27: =Assumptions!F51+Assumptions!F52+(Assumptions!F48+Assumptions!F49+Assumptions!F50+Assumptions!F72)*Assumptions!$C$58 | G27: =Assumptions!G51+Assumptions!G52+(Assumptions!G48+Assumptions!G49+Assumptions!G50+Assumptions!G72)*Assumptions!$C$58
B28: EBITDA | C28: =C26-C27 | D28: =D26-D27 | E28: =E26-E27 | F28: =F26-F27 | G28: =G26-G27
B29: Cumulative EBITDA | C29: =C28 | D29: =C29+D28 | E29: =D29+E28 | F29: =E29+F28 | G29: =F29+G28
B30: profit-year helper | C30: =IF(C28>0,C$60,99) | D30: =IF(D28>0,D$60,99) | E30: =IF(E28>0,E$60,99) | F30: =IF(F28>0,F$60,99) | G30: =IF(G28>0,G$60,99)
B34: SUMMARY
C35: Conservative | D35: Base | E35: Aggressive
B36: Y5 revenue | C36: =G5 | D36: =G15 | E36: =G25
B37: Y5 EBITDA | C37: =G8 | D37: =G18 | E37: =G28
B38: Y5 EBITDA margin | C38: =IF(G5=0,"",G8/G5) | D38: =IF(G15=0,"",G18/G15) | E38: =IF(G25=0,"",G28/G25)
B39: Cumulative cash low-point | C39: =MIN(C9:G9) | D39: =MIN(C19:G19) | E39: =MIN(C29:G29)
B40: Capital need incl. buffer | C40: =-MIN(C9:G9)+Assumptions!$C$11 | D40: =-MIN(C19:G19)+Assumptions!$C$11 | E40: =-MIN(C29:G29)+Assumptions!$C$11
B41: First EBITDA-positive year | C41: ="Y"&MIN(C10:G10) | D41: ="Y"&MIN(C20:G20) | E41: ="Y"&MIN(C30:G30)
B43: CASH RUNWAY CHECK (Base scenario — does the R5m seed cover the trough before the optional Series A?)
B44: Series A closes at start of year (1-5) | C44: 3
B45: Year | C45: Y1 | D45: Y2 | E45: Y3 | F45: Y4 | G45: Y5
B46: Base EBITDA (R) | C46: =C18 | D46: =D18 | E46: =E18 | F46: =F18 | G46: =G18
B47: Funding injected (R) | C47: ='Cap Table'!$C$6+IF(1=$C$44,'Cap Table'!$C$9,0) | D47: =IF(2=$C$44,'Cap Table'!$C$9,0) | E47: =IF(3=$C$44,'Cap Table'!$C$9,0) | F47: =IF(4=$C$44,'Cap Table'!$C$9,0) | G47: =IF(5=$C$44,'Cap Table'!$C$9,0)
B48: Cumulative cash position (R) | C48: =C46+C47 | D48: =C48+D46+D47 | E48: =D48+E46+E47 | F48: =E48+F46+F47 | G48: =F48+G46+G47
B49: Minimum cash position across Y1-Y5 (R) | C49: =MIN(C48:G48)
...

Sheet Market Sizing
B1: Market Sizing — TAM / SAM / SOM (linked to projection)
B2: Amber = input. Grey = calculated/linked. Estimates — sources in the Market sizing document in the data room.
B4: HEADLINE (annual revenue pool)
B6: TAM — all SA residential transfers | C6: =C20
B7: SAM — upper-market (>~R4m), national | C7: =C27
B8: SOM — our base-case Y5 revenue | C8: =D32
B10: 1. THE MARKET CONTEXT (full-service commission pool)
B11: SA annual residential transfers | C11: 250000 | D11: ~207k-277k (Lightstone 2024)
B12: Avg transaction price - national (R) | C12: 1400000 | D12: Lightstone Q1 2024
B13: Total annual transaction value (R) | C13: =C11*C12 | D13: ~R350bn
B14: Avg agent commission incl VAT (%) | C14: 0.069 | D14: 6% x 1.15 VAT
B15: Agent commission pool / yr (R) | C15: =C13*C14 | D15: ~R24bn - what sellers pay for full service (context for the private-sale segment we serve)
B17: 2. TAM - addressable revenue pool (all SA transfers)
B18: SA transfers / yr | C18: =C11
B19: Our blended revenue / deal - national (R) | C19: 25000 | D19: 1% fee/referral + conveyancing + ecosystem, ~R1.4m home
B20: TAM revenue pool / yr (R) | C20: =C18*C19 | D20: ~R6.3bn
B22: 3. SAM - serviceable: UPPER-MARKET (>~R4m), national
B23: Upper-market (>~R4m) transfers / yr | C23: 35000 | D23: Estimate — broadens as the average price tapers
B24: Avg prime transacting price (R) | C24: =Assumptions!C15 | D24: linked to model price
B25: Prime transaction value / yr (R) | C25: =C23*C24 | D25: ~R91bn
B26: Our revenue / deal - prime (R) | C26: =Assumptions!G23 | D26: linked to model Y5 rev/deal
B27: SAM revenue pool / yr (R) | C27: =C23*C26 | D27: ~R0.98bn
B29: 4. SOM - obtainable (our projection, linked)
C30: Conservative | D30: Base | E30: Aggressive
B31: Y5 registered deals | C31: =Assumptions!G31 | D31: =Assumptions!G32 | E31: =Assumptions!G33
B32: Y5 revenue (R) | C32: =Scenarios!C36 | D32: =Scenarios!D36 | E32: =Scenarios!E36
B33: SOM = % of upper-market transactions | C33: =C31/$C$23 | D33: =D31/$C$23 | E33: =E31/$C$23
B34: SOM = % of prime revenue pool | C34: =C32/$C$27 | D34: =D32/$C$27 | E34: =E32/$C$27
B35: For reference: % of ALL SA transfers | C35: =C31/$C$11 | D35: =D31/$C$11 | E35: =E31/$C$11
B37: 5. STRESS TEST / reality check
B38: Base implies this share of the upper-market by Y5 | C38: =D33
B39: Implied prime share moves inversely with the prime-pool estimate:
B40: If pool = 25,000 -> base Y5 share | C40: =D31/25000
B41: If pool = 35,000 (base) -> base Y5 share | C41: =D31/35000
B42: If pool = 50,000 -> base Y5 share | C42: =D31/50000
B44: POSITIONING: tapering price broadens the addressable pool, cutting the implied share from ~21% (prime-only) to ~8%.
B45: Land at prime (biggest rand savings + bond), expand down to upper-mid as the brand scales. As % of ALL SA transfers: ~1.2%.
B47: 6. CONSUMER VALUE - KEPT VS FULL-SERVICE BENCHMARK (sellers who choose self-service)
C48: Y1 | D48: Y2 | E48: Y3 | F48: Y4 | G48: Y5
B49: Avg sale price (R) | C49: =Assumptions!C15 | D49: =Assumptions!D15 | E49: =Assumptions!E15 | F49: =Assumptions!F15 | G49: =Assumptions!G15
...

Sheet Capital & Valuation
B1: Capital Requirement & Valuation
B3: CAPITAL (from Scenarios)
C4: Conservative | D4: Base | E4: Aggressive
B5: Total capital to breakeven (R) | C5: =Scenarios!C40 | D5: =Scenarios!D40 | E5: =Scenarios!E40
B6: in USD (approx) | C6: =C5/Assumptions!$C$8 | D6: =D5/Assumptions!$C$8 | E6: =E5/Assumptions!$C$8
B8: RECOMMENDED RAISE
B9: Seed round (R) — lean R5m seed (Oct 2026) | C9: 5000000
B10: Seed round (USD approx) | C10: =C9/Assumptions!$C$8
B12: VALUATION — REVENUE MULTIPLE (Base, Y5)
C13: Low | D13: High
B14: Y5 revenue (R) | C14: =Scenarios!D36 | D14: =Scenarios!D36
B15: Revenue multiple | C15: =Assumptions!C9 | D15: =Assumptions!C10
B16: Enterprise value (R) | C16: =C14*C15 | D16: =D14*D15
B17: Enterprise value (USD) | C17: =C16/Assumptions!$C$8 | D17: =D16/Assumptions!$C$8
B19: SEED ROUND TERMS (live — drives Cap Table dilution)
B20: Seed pre-money (R) | C20: 20000000
B21: Seed raise (R) | C21: =C9
B22: Seed post-money (R) | C22: =C20+C21
B23: New-investor stake | C23: =C21/C22
B25: AGGRESSIVE UPSIDE
B26: Y5 revenue (R) | C26: =Scenarios!E36
B27: EV @ 5x (R) | C27: =C26*Assumptions!$C$75

Sheet Use of Funds
B1: Use of Funds — seed round
B2: Amber = editable allocation. % and totals calculated. Seed amount linked from Capital & Valuation!C9.
B4: Category | C4: Amount (R) | D4: % | E4: What it buys / milestone
B5: Above-the-line / brand marketing | C5: 2000000 | D5: =C5/$C$11 | E5: Cape Town launch + brand campaign in prime CT — the deal-ramp engine; prove ATL→deals conversion
B6: Team (four people: founders, principal practitioner, agent/admin) | C6: 1200000 | D6: =C6/$C$11 | E6: Four-person launch team at R150k/month — founders at R50k each carry marketing, management, dealmaking, bookkeeping and tech support; hires beyond four only against signed mandates
B7: Product & technology | C7: 500000 | D7: =C7/$C$11 | E7: WhatsApp BSP, deal tracker, dashboard, security — Paysoft free-development allocation carries most of the build
B8: Partnerships & go-to-market | C8: 400000 | D8: =C8/$C$11 | E8: BetterBond + panel conveyancers live; secure the bank headline sponsor; Property24 feed
B9: Legal / compliance / licensing | C9: 500000 | D9: =C9/$C$11 | E9: PPRA practitioner + FFC, POPIA programme, contracts, mandate templates, FAIS/FSP groundwork
B10: Working capital / contingency | C10: 400000 | D10: =C10/$C$11 | E10: Buffer above the modelled Y1 cash trough
B11: Total allocated | C11: =SUM(C5:C10) | D11: =C11/$C$11
B12: Seed raise (linked) | C12: ='Capital & Valuation'!C9
B13: Check (allocated − seed; should be 0) | C13: =C11-C12
B15: Note: the four-person launch team with no office keeps the modelled cash trough small; most of the R5m is launch marketing and runway headroom in every scenario.

Sheet Cap Table
B1: Cap Table — ownership & dilution
B2: No separate founding round — the Strategic Funder and the technology partner come in at inception alongside the working founders. Johannes le Roux 32.5% · Dean Kruger 32.5% · Paysoft (technology partner, vesting against preferred rates + free development) 10% · option pool (reserved) 4% · board seat (reserved, non-executive) 1% · Strategic Funder R5m for 20% (R20m pre / R25m post). Founder shares reverse-vest over 36 months. Amber = editable inputs; round economics linked from Capital & Valuation.
B4: ROUND INPUTS
B5: Seed pre-money (R) | C5: ='Capital & Valuation'!C20
B6: Seed raise (R) | C6: ='Capital & Valuation'!C9
B7: Seed post-money (R) | C7: =C5+C6
B8: Series A pre-money (R) | C8: 125000000
B9: Series A raise (R) | C9: 25000000
B10: Series A post-money (R) | C10: =C8+C9
B11: Exit multiple (x Y5 revenue) | C11: =Assumptions!C75
B12: Exit enterprise value — base Y5 (R) | C12: =Scenarios!D36*C11
B14: OWNERSHIP (%)
B15: Holder | C15: Seed | D15: Series A
B16: Johannes le Roux — Marketing Director | C16: 0.325 | D16: =C16*($C$8/$C$10)
B17: Dean Kruger — Managing Director | C17: 0.325 | D17: =C17*($C$8/$C$10)
B18: Paysoft — Technology Partner (vesting) | C18: 0.1 | D18: =C18*($C$8/$C$10)
B19: Option pool (reserved, unissued) | C19: 0.04 | D19: =C19*($C$8/$C$10)
B20: Board seat (reserved, non-executive) | C20: 0.01 | D20: =C20*($C$8/$C$10)
B21: Strategic Funder / Seed Investor | C21: =$C$6/$C$7 | D21: =C21*($C$8/$C$10)
B22: Series A Investor | C22: 0 | D22: =$C$9/$C$10
B23: Total | C23: =SUM(C16:C22) | D23: =SUM(D16:D22)
B25: VALUE OF STAKE (R)
B26: Holder | C26: ="At Seed (R"&TEXT(C7/1000000,"0")&"m)" | D26: At Series A | E26: At Exit
B27: Johannes le Roux — Marketing Director | C27: =C16*$C$7 | D27: =D16*$C$10 | E27: =D16*$C$12
B28: Dean Kruger — Managing Director | C28: =C17*$C$7 | D28: =D17*$C$10 | E28: =D17*$C$12
B29: Paysoft — Technology Partner (vesting) | C29: =C18*$C$7 | D29: =D18*$C$10 | E29: =D18*$C$12
B30: Option pool (reserved, unissued) | C30: =C19*$C$7 | D30: =D19*$C$10 | E30: =D19*$C$12
B31: Board seat (reserved, non-executive) | C31: =C20*$C$7 | D31: =D20*$C$10 | E31: =D20*$C$12
B32: Strategic Funder / Seed Investor | C32: =C21*$C$7 | D32: =D21*$C$10 | E32: =D21*$C$12
B33: Series A Investor | C33: =C22*$C$7 | D33: =D22*$C$10 | E33: =D22*$C$12
B34: Total | C34: =SUM(C27:C33) | D34: =SUM(D27:D33) | E34: =SUM(E27:E33)

Sheet Competitive Landscape
B1: Competitive Landscape
B2: Sold Direct is the only 0%-to-consumer player that monetises the financial ecosystem around the deal via WhatsApp.
B4: Player | C4: Model | D4: Cost to seller | E4: Channel | F4: Bond / finance | G4: Ecosystem revenue | H4: Segment / status
B5: Sold Direct | C5: 0% marketplace + concierge | D5: 0% (1% non-partner) | E5: WhatsApp-native | F5: Multi-bank origination referral (core) | G5: Yes — insurance, solar, moving, life cover… | H5: Prime first; launching
B6: Traditional agencies (Pam Golding, Seeff, Rawson) | C6: Full-service agency | D6: 5–7% + VAT | E6: Agents + portals | F6: Refer to originators | G6: Limited (referrals) | H6: Full-service sellers; established, commission-funded
B7: Property24 | C7: Listings portal | D7: Portal fees (to agents) | E7: Web / app portal | F7: Bond calculators & leads | G7: Ad / lead revenue | H7: All; dominant portal (Prosus)
B8: Private Property | C8: Listings portal | D8: Listing / portal fees | E8: Web portal | F8: Bond referral | G8: Ad / lead revenue | H8: All; #2 portal
B9: PropertyFox | C9: Low-commission hybrid | D9: ~1.5% flat | E9: Online + agents | F9: — | G9: Limited | H9: Mid; struggled / sold — cautionary
B10: Leadhome | C10: Fixed-fee online agency | D10: Low fixed fee | E10: Online + agents | F10: — | G10: Limited | H10: Mid; wound down — cautionary
B11: ooba / BetterBond | C11: Bond originators | D11: Free to consumer | E11: Web / agents | F11: Core business | G11: — | H11: Bonded buyers — PARTNERS, not rivals
B12: Purplebricks (UK) | C12: Fixed-fee online agency | D12: Fixed fee | E12: Online | F12: — | G12: Limited | H12: Defunct: £240m IPO → £1 — CAC warning
B14: NOTE: Traditional agents serve the full-service segment - complementary, not a target. Sold Direct serves sellers who choose to sell privately, assisted by our own employed, registered practitioners (PPRA/FFC).

Sheet Ancillary Revenue
B1: Ancillary / Ecosystem Revenue — the value of the database
B2: Referral & commission streams unlocked by owning the homeowner relationship + data. Optional: toggle into the P&L on Assumptions!C61.
B4: Revenue stream | C4: Low (R) | D4: High (R) | E4: Midpoint (R) | F4: Attach % | G4: Captured/deal (R)
B5: Homeowners insurance commission | C5: 1500 | D5: 4000 | E5: =AVERAGE(C5:D5) | F5: 0.3 | G5: =E5*F5
B6: Household contents insurance | C6: 500 | D6: 2000 | E6: =AVERAGE(C6:D6) | F6: 0.25 | G6: =E6*F6
B7: Conveyancing — no referral fee (LPC); panel advertising is a fixed line in core Other Revenue | C7: 3000 | D7: 8000 | E7: =AVERAGE(C7:D7) | F7: 0 | G7: =E7*F7
B8: Moving company referral | C8: 500 | D8: 2000 | E8: =AVERAGE(C8:D8) | F8: 0.2 | G8: =E8*F8
B9: Fibre / internet installation | C9: 500 | D9: 1500 | E9: =AVERAGE(C9:D9) | F9: 0.2 | G9: =E9*F9
B10: Security system installation | C10: 1000 | D10: 3000 | E10: =AVERAGE(C10:D10) | F10: 0.15 | G10: =E10*F10
B11: Utility connection service | C11: 250 | D11: 1000 | E11: =AVERAGE(C11:D11) | F11: 0.3 | G11: =E11*F11
B12: Home warranty / product upsell | C12: 500 | D12: 2500 | E12: =AVERAGE(C12:D12) | F12: 0.1 | G12: =E12*F12
B13: Compliance certificates (already in core add-ons) | C13: 500 | D13: 2000 | E13: =AVERAGE(C13:D13) | F13: 0 | G13: =E13*F13
B14: Solar installation referral | C14: 5000 | D14: 20000 | E14: =AVERAGE(C14:D14) | F14: 0.05 | G14: =E14*F14
B15: Home improvement / renovation referrals | C15: 2000 | D15: 15000 | E15: =AVERAGE(C15:D15) | F15: 0.08 | G15: =E15*F15
B16: Storage solutions referral | C16: 500 | D16: 2000 | E16: =AVERAGE(C16:D16) | F16: 0.1 | G16: =E16*F16
... B19: Estate planning / will services | C19: 500 | D19: 2000 | E19: =AVERAGE(C19:D19) | F19: 0.1 | G19: =E19*F19
B21: FULL ecosystem potential / customer (sum of midpoints) | E21: =SUM(E5:E19)
B22: Realistic ADDITIONAL captured / deal (sum of captured) | G22: =SUM(G5:G19)
B24: Conveyancing & compliance certs are already counted in the core model (attach set to 0 here to avoid double-counting).
B25: Strategic point: each registered customer is worth up to ~R50k of ecosystem referral revenue. Even ~10% capture ≈ R5k/deal — the database is the moat.

Sheet Notes & Sources
B1: Sold Direct — model notes & sources
B3: Strategy: prime / upper-market focus (Atlantic Seaboard, City Bowl, Southern Suburbs, Constantia; then prime JHB-north & Umhlanga).
B5: MONETISATION (legally clean - no bank exclusivity):
B6: • Free 0% requires a qualifying >=80% bond; seller appoints a panel conveyancer (30–40% fee discount passed to the consumer — CPA s13 benefit); buyer keeps full rate choice. Y1: placed via our MULTI-BANK originator (ooba) — referral ~0.5% of bond. Y2+: origination goes IN-HOUSE, direct with the banks (full commission ~1.5% of bond, ~3x the referral) — needs bank aggregation agreements + FAIS/FSP accreditation; Y1 via ooba is the runway to secure them. Conveyancer revenue is a FIXED panel-advertising subscription (never per-deal) — LPC Rules 12/18.10/18.22 prohibit attorney referral fees.
B7: • Otherwise a 1% facilitation fee on the price (cash / sub-80% / not using our partners) - ~6x less than a typical full-service commission (5-7% + VAT), stated as a neutral benchmark.
B8: • Bank HEADLINE SPONSORSHIP: a bank pays an annual fee to be the featured sponsor / brand on the platform (advertising, not steering) - high-margin, grows with audience.
B10: THE DATABASE / ECOSYSTEM (see Ancillary Revenue tab):
B11: • Owning the homeowner relationship unlocks a referral menu worth ~R50k of ecosystem revenue per customer (insurance, solar, moving, fibre, security, life cover, etc.).
B12: • Modelled conservatively as OPTIONAL: ~R5k additional captured per deal (~10% blended capture). Toggle into the P&L on Assumptions!C61 (default off).
B13: • This is the moat and the expansion-revenue story - default off keeps the headline P&L conservative; turning it on adds ~R14m to Y5 base revenue.
B15: TECHNOLOGY-LEAN OPERATING MODEL:
B16: • 50% of headcount are automated roles (concierge/coordination/ops) at ~R0.15m/yr each vs ~R0.70-0.78m/yr fully-loaded human - roughly halves people-cost.
... B27: HOW TO USE: edit amber cells on Assumptions. P&L, Scenarios and Valuation recalculate automatically.
